[2023-09-14T07:58:49.828+0000] {taskinstance.py:1157} INFO - Dependencies all met for dep_context=non-requeueable deps ti=<TaskInstance: etl_dag.update_postgres_table scheduled__2023-09-13T00:00:00+00:00 [queued]>
[2023-09-14T07:58:49.831+0000] {taskinstance.py:1157} INFO - Dependencies all met for dep_context=requeueable deps ti=<TaskInstance: etl_dag.update_postgres_table scheduled__2023-09-13T00:00:00+00:00 [queued]>
[2023-09-14T07:58:49.832+0000] {taskinstance.py:1359} INFO - Starting attempt 1 of 2
[2023-09-14T07:58:49.838+0000] {taskinstance.py:1380} INFO - Executing <Task(PythonOperator): update_postgres_table> on 2023-09-13 00:00:00+00:00
[2023-09-14T07:58:49.840+0000] {standard_task_runner.py:57} INFO - Started process 60 to run task
[2023-09-14T07:58:49.842+0000] {standard_task_runner.py:84} INFO - Running: ['***', 'tasks', 'run', 'etl_dag', 'update_postgres_table', 'scheduled__2023-09-13T00:00:00+00:00', '--job-id', '3', '--raw', '--subdir', 'DAGS_FOLDER/etl_dag.py', '--cfg-path', '/tmp/tmpvdq0i9jp']
[2023-09-14T07:58:49.844+0000] {standard_task_runner.py:85} INFO - Job 3: Subtask update_postgres_table
[2023-09-14T07:58:49.873+0000] {task_command.py:415} INFO - Running <TaskInstance: etl_dag.update_postgres_table scheduled__2023-09-13T00:00:00+00:00 [running]> on host 0246784cd362
[2023-09-14T07:58:50.019+0000] {taskinstance.py:1660} INFO - Exporting env vars: AIRFLOW_CTX_DAG_OWNER='admin' AIRFLOW_CTX_DAG_ID='etl_dag' AIRFLOW_CTX_TASK_ID='update_postgres_table' AIRFLOW_CTX_EXECUTION_DATE='2023-09-13T00:00:00+00:00' AIRFLOW_CTX_TRY_NUMBER='1' AIRFLOW_CTX_DAG_RUN_ID='scheduled__2023-09-13T00:00:00+00:00'
[2023-09-14T07:58:50.026+0000] {taskinstance.py:1935} ERROR - Task failed with exception
Traceback (most recent call last):
  File "/home/airflow/.local/lib/python3.8/site-packages/airflow/operators/python.py", line 192, in execute
    return_value = self.execute_callable()
  File "/home/airflow/.local/lib/python3.8/site-packages/airflow/operators/python.py", line 209, in execute_callable
    return self.python_callable(*self.op_args, **self.op_kwargs)
  File "/opt/airflow/dags/etl_dag.py", line 36, in _update_postgres_table
    connection = json.loads(extract_connection)
NameError: name 'json' is not defined
[2023-09-14T07:58:50.033+0000] {taskinstance.py:1398} INFO - Marking task as UP_FOR_RETRY. dag_id=etl_dag, task_id=update_postgres_table, execution_date=20230913T000000, start_date=20230914T075849, end_date=20230914T075850
[2023-09-14T07:58:50.038+0000] {standard_task_runner.py:104} ERROR - Failed to execute job 3 for task update_postgres_table (name 'json' is not defined; 60)
[2023-09-14T07:58:50.056+0000] {local_task_job_runner.py:228} INFO - Task exited with return code 1
[2023-09-14T07:58:50.067+0000] {taskinstance.py:2776} INFO - 0 downstream tasks scheduled from follow-on schedule check
[2023-09-14T09:24:34.701+0000] {taskinstance.py:1157} INFO - Dependencies all met for dep_context=non-requeueable deps ti=<TaskInstance: etl_dag.update_postgres_table scheduled__2023-09-13T00:00:00+00:00 [queued]>
[2023-09-14T09:24:34.705+0000] {taskinstance.py:1157} INFO - Dependencies all met for dep_context=requeueable deps ti=<TaskInstance: etl_dag.update_postgres_table scheduled__2023-09-13T00:00:00+00:00 [queued]>
[2023-09-14T09:24:34.705+0000] {taskinstance.py:1359} INFO - Starting attempt 1 of 2
[2023-09-14T09:24:34.711+0000] {taskinstance.py:1380} INFO - Executing <Task(PythonOperator): update_postgres_table> on 2023-09-13 00:00:00+00:00
[2023-09-14T09:24:34.713+0000] {standard_task_runner.py:57} INFO - Started process 235 to run task
[2023-09-14T09:24:34.716+0000] {standard_task_runner.py:84} INFO - Running: ['***', 'tasks', 'run', 'etl_dag', 'update_postgres_table', 'scheduled__2023-09-13T00:00:00+00:00', '--job-id', '4', '--raw', '--subdir', 'DAGS_FOLDER/etl_dag.py', '--cfg-path', '/tmp/tmpjx28_n7p']
[2023-09-14T09:24:34.717+0000] {standard_task_runner.py:85} INFO - Job 4: Subtask update_postgres_table
[2023-09-14T09:24:34.749+0000] {task_command.py:415} INFO - Running <TaskInstance: etl_dag.update_postgres_table scheduled__2023-09-13T00:00:00+00:00 [running]> on host c734f2da7931
[2023-09-14T09:24:34.792+0000] {taskinstance.py:1660} INFO - Exporting env vars: AIRFLOW_CTX_DAG_OWNER='admin' AIRFLOW_CTX_DAG_ID='etl_dag' AIRFLOW_CTX_TASK_ID='update_postgres_table' AIRFLOW_CTX_EXECUTION_DATE='2023-09-13T00:00:00+00:00' AIRFLOW_CTX_TRY_NUMBER='1' AIRFLOW_CTX_DAG_RUN_ID='scheduled__2023-09-13T00:00:00+00:00'
[2023-09-14T09:24:34.907+0000] {taskinstance.py:1935} ERROR - Task failed with exception
Traceback (most recent call last):
  File "/home/airflow/.local/lib/python3.8/site-packages/airflow/operators/python.py", line 192, in execute
    return_value = self.execute_callable()
  File "/home/airflow/.local/lib/python3.8/site-packages/airflow/operators/python.py", line 209, in execute_callable
    return self.python_callable(*self.op_args, **self.op_kwargs)
  File "/opt/airflow/dags/etl_dag.py", line 35, in _update_postgres_table
    connection = json.loads(extract_connection)
NameError: name 'json' is not defined
[2023-09-14T09:24:34.915+0000] {taskinstance.py:1398} INFO - Marking task as UP_FOR_RETRY. dag_id=etl_dag, task_id=update_postgres_table, execution_date=20230913T000000, start_date=20230914T092434, end_date=20230914T092434
[2023-09-14T09:24:34.920+0000] {standard_task_runner.py:104} ERROR - Failed to execute job 4 for task update_postgres_table (name 'json' is not defined; 235)
[2023-09-14T09:24:34.932+0000] {local_task_job_runner.py:228} INFO - Task exited with return code 1
[2023-09-14T09:24:34.946+0000] {taskinstance.py:2776} INFO - 0 downstream tasks scheduled from follow-on schedule check
[2023-09-14T09:28:27.735+0000] {taskinstance.py:1157} INFO - Dependencies all met for dep_context=non-requeueable deps ti=<TaskInstance: etl_dag.update_postgres_table scheduled__2023-09-13T00:00:00+00:00 [queued]>
[2023-09-14T09:28:27.738+0000] {taskinstance.py:1157} INFO - Dependencies all met for dep_context=requeueable deps ti=<TaskInstance: etl_dag.update_postgres_table scheduled__2023-09-13T00:00:00+00:00 [queued]>
[2023-09-14T09:28:27.739+0000] {taskinstance.py:1359} INFO - Starting attempt 1 of 2
[2023-09-14T09:28:27.743+0000] {taskinstance.py:1380} INFO - Executing <Task(PythonOperator): update_postgres_table> on 2023-09-13 00:00:00+00:00
[2023-09-14T09:28:27.745+0000] {standard_task_runner.py:57} INFO - Started process 62 to run task
[2023-09-14T09:28:27.748+0000] {standard_task_runner.py:84} INFO - Running: ['***', 'tasks', 'run', 'etl_dag', 'update_postgres_table', 'scheduled__2023-09-13T00:00:00+00:00', '--job-id', '4', '--raw', '--subdir', 'DAGS_FOLDER/etl_dag.py', '--cfg-path', '/tmp/tmpz402sx4t']
[2023-09-14T09:28:27.749+0000] {standard_task_runner.py:85} INFO - Job 4: Subtask update_postgres_table
[2023-09-14T09:28:27.774+0000] {task_command.py:415} INFO - Running <TaskInstance: etl_dag.update_postgres_table scheduled__2023-09-13T00:00:00+00:00 [running]> on host 7a3bfad172a7
[2023-09-14T09:28:27.807+0000] {taskinstance.py:1660} INFO - Exporting env vars: AIRFLOW_CTX_DAG_OWNER='admin' AIRFLOW_CTX_DAG_ID='etl_dag' AIRFLOW_CTX_TASK_ID='update_postgres_table' AIRFLOW_CTX_EXECUTION_DATE='2023-09-13T00:00:00+00:00' AIRFLOW_CTX_TRY_NUMBER='1' AIRFLOW_CTX_DAG_RUN_ID='scheduled__2023-09-13T00:00:00+00:00'
[2023-09-14T09:28:27.895+0000] {taskinstance.py:1935} ERROR - Task failed with exception
Traceback (most recent call last):
  File "/home/airflow/.local/lib/python3.8/site-packages/airflow/operators/python.py", line 192, in execute
    return_value = self.execute_callable()
  File "/home/airflow/.local/lib/python3.8/site-packages/airflow/operators/python.py", line 209, in execute_callable
    return self.python_callable(*self.op_args, **self.op_kwargs)
  File "/opt/airflow/dags/etl_dag.py", line 35, in _update_postgres_table
    connection = json.loads(extract_connection)
NameError: name 'json' is not defined
[2023-09-14T09:28:27.901+0000] {taskinstance.py:1398} INFO - Marking task as UP_FOR_RETRY. dag_id=etl_dag, task_id=update_postgres_table, execution_date=20230913T000000, start_date=20230914T092827, end_date=20230914T092827
[2023-09-14T09:28:27.906+0000] {standard_task_runner.py:104} ERROR - Failed to execute job 4 for task update_postgres_table (name 'json' is not defined; 62)
[2023-09-14T09:28:27.923+0000] {local_task_job_runner.py:228} INFO - Task exited with return code 1
[2023-09-14T09:28:27.935+0000] {taskinstance.py:2776} INFO - 0 downstream tasks scheduled from follow-on schedule check
[2023-09-14T09:34:59.031+0000] {taskinstance.py:1157} INFO - Dependencies all met for dep_context=non-requeueable deps ti=<TaskInstance: etl_dag.update_postgres_table scheduled__2023-09-13T00:00:00+00:00 [queued]>
[2023-09-14T09:34:59.035+0000] {taskinstance.py:1157} INFO - Dependencies all met for dep_context=requeueable deps ti=<TaskInstance: etl_dag.update_postgres_table scheduled__2023-09-13T00:00:00+00:00 [queued]>
[2023-09-14T09:34:59.035+0000] {taskinstance.py:1359} INFO - Starting attempt 1 of 2
[2023-09-14T09:34:59.039+0000] {taskinstance.py:1380} INFO - Executing <Task(PythonOperator): update_postgres_table> on 2023-09-13 00:00:00+00:00
[2023-09-14T09:34:59.042+0000] {standard_task_runner.py:57} INFO - Started process 79 to run task
[2023-09-14T09:34:59.044+0000] {standard_task_runner.py:84} INFO - Running: ['***', 'tasks', 'run', 'etl_dag', 'update_postgres_table', 'scheduled__2023-09-13T00:00:00+00:00', '--job-id', '4', '--raw', '--subdir', 'DAGS_FOLDER/etl_dag.py', '--cfg-path', '/tmp/tmp_p0ig8ef']
[2023-09-14T09:34:59.045+0000] {standard_task_runner.py:85} INFO - Job 4: Subtask update_postgres_table
[2023-09-14T09:34:59.071+0000] {task_command.py:415} INFO - Running <TaskInstance: etl_dag.update_postgres_table scheduled__2023-09-13T00:00:00+00:00 [running]> on host 79bfd5ddbbec
[2023-09-14T09:34:59.104+0000] {taskinstance.py:1660} INFO - Exporting env vars: AIRFLOW_CTX_DAG_OWNER='admin' AIRFLOW_CTX_DAG_ID='etl_dag' AIRFLOW_CTX_TASK_ID='update_postgres_table' AIRFLOW_CTX_EXECUTION_DATE='2023-09-13T00:00:00+00:00' AIRFLOW_CTX_TRY_NUMBER='1' AIRFLOW_CTX_DAG_RUN_ID='scheduled__2023-09-13T00:00:00+00:00'
[2023-09-14T09:34:59.193+0000] {taskinstance.py:1935} ERROR - Task failed with exception
Traceback (most recent call last):
  File "/home/airflow/.local/lib/python3.8/site-packages/airflow/operators/python.py", line 192, in execute
    return_value = self.execute_callable()
  File "/home/airflow/.local/lib/python3.8/site-packages/airflow/operators/python.py", line 209, in execute_callable
    return self.python_callable(*self.op_args, **self.op_kwargs)
  File "/opt/airflow/dags/etl_dag.py", line 35, in _update_postgres_table
    connection = json.loads(extract_connection)
NameError: name 'json' is not defined
[2023-09-14T09:34:59.199+0000] {taskinstance.py:1398} INFO - Marking task as UP_FOR_RETRY. dag_id=etl_dag, task_id=update_postgres_table, execution_date=20230913T000000, start_date=20230914T093459, end_date=20230914T093459
[2023-09-14T09:34:59.204+0000] {standard_task_runner.py:104} ERROR - Failed to execute job 4 for task update_postgres_table (name 'json' is not defined; 79)
[2023-09-14T09:34:59.222+0000] {local_task_job_runner.py:228} INFO - Task exited with return code 1
[2023-09-14T09:34:59.235+0000] {taskinstance.py:2776} INFO - 0 downstream tasks scheduled from follow-on schedule check
