[2023-09-18T00:24:45.397+0000] {taskinstance.py:1157} INFO - Dependencies all met for dep_context=non-requeueable deps ti=<TaskInstance: etl_dag.update_pg scheduled__2023-09-17T00:00:00+00:00 [queued]>
[2023-09-18T00:24:45.402+0000] {taskinstance.py:1157} INFO - Dependencies all met for dep_context=requeueable deps ti=<TaskInstance: etl_dag.update_pg scheduled__2023-09-17T00:00:00+00:00 [queued]>
[2023-09-18T00:24:45.402+0000] {taskinstance.py:1359} INFO - Starting attempt 1 of 2
[2023-09-18T00:24:45.407+0000] {taskinstance.py:1380} INFO - Executing <Task(PythonOperator): update_pg> on 2023-09-17 00:00:00+00:00
[2023-09-18T00:24:45.410+0000] {standard_task_runner.py:57} INFO - Started process 591 to run task
[2023-09-18T00:24:45.412+0000] {standard_task_runner.py:84} INFO - Running: ['***', 'tasks', 'run', 'etl_dag', 'update_pg', 'scheduled__2023-09-17T00:00:00+00:00', '--job-id', '7', '--raw', '--subdir', 'DAGS_FOLDER/etl_dag.py', '--cfg-path', '/tmp/tmpsc85j0b3']
[2023-09-18T00:24:45.414+0000] {standard_task_runner.py:85} INFO - Job 7: Subtask update_pg
[2023-09-18T00:24:45.440+0000] {task_command.py:415} INFO - Running <TaskInstance: etl_dag.update_pg scheduled__2023-09-17T00:00:00+00:00 [running]> on host d505fbb7204f
[2023-09-18T00:24:45.562+0000] {taskinstance.py:1660} INFO - Exporting env vars: AIRFLOW_CTX_DAG_OWNER='admin' AIRFLOW_CTX_DAG_ID='etl_dag' AIRFLOW_CTX_TASK_ID='update_pg' AIRFLOW_CTX_EXECUTION_DATE='2023-09-17T00:00:00+00:00' AIRFLOW_CTX_TRY_NUMBER='1' AIRFLOW_CTX_DAG_RUN_ID='scheduled__2023-09-17T00:00:00+00:00'
[2023-09-18T00:24:45.612+0000] {taskinstance.py:1935} ERROR - Task failed with exception
Traceback (most recent call last):
  File "/home/airflow/.local/lib/python3.8/site-packages/urllib3/connection.py", line 174, in _new_conn
    conn = connection.create_connection(
  File "/home/airflow/.local/lib/python3.8/site-packages/urllib3/util/connection.py", line 72, in create_connection
    for res in socket.getaddrinfo(host, port, family, socket.SOCK_STREAM):
  File "/usr/local/lib/python3.8/socket.py", line 918, in getaddrinfo
    for res in _socket.getaddrinfo(host, port, family, type, proto, flags):
socket.gaierror: [Errno -3] Temporary failure in name resolution

During handling of the above exception, another exception occurred:

Traceback (most recent call last):
  File "/home/airflow/.local/lib/python3.8/site-packages/urllib3/connectionpool.py", line 714, in urlopen
    httplib_response = self._make_request(
  File "/home/airflow/.local/lib/python3.8/site-packages/urllib3/connectionpool.py", line 403, in _make_request
    self._validate_conn(conn)
  File "/home/airflow/.local/lib/python3.8/site-packages/urllib3/connectionpool.py", line 1053, in _validate_conn
    conn.connect()
  File "/home/airflow/.local/lib/python3.8/site-packages/urllib3/connection.py", line 363, in connect
    self.sock = conn = self._new_conn()
  File "/home/airflow/.local/lib/python3.8/site-packages/urllib3/connection.py", line 186, in _new_conn
    raise NewConnectionError(
urllib3.exceptions.NewConnectionError: <urllib3.connection.HTTPSConnection object at 0xffff74a685b0>: Failed to establish a new connection: [Errno -3] Temporary failure in name resolution

During handling of the above exception, another exception occurred:

Traceback (most recent call last):
  File "/home/airflow/.local/lib/python3.8/site-packages/requests/adapters.py", line 486, in send
    resp = conn.urlopen(
  File "/home/airflow/.local/lib/python3.8/site-packages/urllib3/connectionpool.py", line 798, in urlopen
    retries = retries.increment(
  File "/home/airflow/.local/lib/python3.8/site-packages/urllib3/util/retry.py", line 592, in increment
    raise MaxRetryError(_pool, url, error or ResponseError(cause))
urllib3.exceptions.MaxRetryError: HTTPSConnectionPool(host='raw.githubusercontent.com', port=443): Max retries exceeded with url: /datasets/london-crime/master/data/crime-rates.csv (Caused by NewConnectionError('<urllib3.connection.HTTPSConnection object at 0xffff74a685b0>: Failed to establish a new connection: [Errno -3] Temporary failure in name resolution'))

During handling of the above exception, another exception occurred:

Traceback (most recent call last):
  File "/home/airflow/.local/lib/python3.8/site-packages/airflow/operators/python.py", line 192, in execute
    return_value = self.execute_callable()
  File "/home/airflow/.local/lib/python3.8/site-packages/airflow/operators/python.py", line 209, in execute_callable
    return self.python_callable(*self.op_args, **self.op_kwargs)
  File "/opt/airflow/dags/etl_dag.py", line 7, in update_pg_wrapper
    update_pg()
  File "/opt/airflow/dags/csv_to_postgres.py", line 45, in update_pg
    data = extract_data_from_url(csv_url)
  File "/opt/airflow/dags/csv_to_postgres.py", line 21, in extract_data_from_url
    response = requests.get(url)
  File "/home/airflow/.local/lib/python3.8/site-packages/requests/api.py", line 73, in get
    return request("get", url, params=params, **kwargs)
  File "/home/airflow/.local/lib/python3.8/site-packages/requests/api.py", line 59, in request
    return session.request(method=method, url=url, **kwargs)
  File "/home/airflow/.local/lib/python3.8/site-packages/requests/sessions.py", line 589, in request
    resp = self.send(prep, **send_kwargs)
  File "/home/airflow/.local/lib/python3.8/site-packages/requests/sessions.py", line 703, in send
    r = adapter.send(request, **kwargs)
  File "/home/airflow/.local/lib/python3.8/site-packages/requests/adapters.py", line 519, in send
    raise ConnectionError(e, request=request)
requests.exceptions.ConnectionError: HTTPSConnectionPool(host='raw.githubusercontent.com', port=443): Max retries exceeded with url: /datasets/london-crime/master/data/crime-rates.csv (Caused by NewConnectionError('<urllib3.connection.HTTPSConnection object at 0xffff74a685b0>: Failed to establish a new connection: [Errno -3] Temporary failure in name resolution'))
[2023-09-18T00:24:45.622+0000] {taskinstance.py:1398} INFO - Marking task as UP_FOR_RETRY. dag_id=etl_dag, task_id=update_pg, execution_date=20230917T000000, start_date=20230918T002445, end_date=20230918T002445
[2023-09-18T00:24:45.626+0000] {standard_task_runner.py:104} ERROR - Failed to execute job 7 for task update_pg (HTTPSConnectionPool(host='raw.githubusercontent.com', port=443): Max retries exceeded with url: /datasets/london-crime/master/data/crime-rates.csv (Caused by NewConnectionError('<urllib3.connection.HTTPSConnection object at 0xffff74a685b0>: Failed to establish a new connection: [Errno -3] Temporary failure in name resolution')); 591)
[2023-09-18T00:24:45.665+0000] {local_task_job_runner.py:228} INFO - Task exited with return code 1
[2023-09-18T00:24:45.676+0000] {taskinstance.py:2776} INFO - 0 downstream tasks scheduled from follow-on schedule check
