[2023-09-14T09:36:16.098+0000] {taskinstance.py:1157} INFO - Dependencies all met for dep_context=non-requeueable deps ti=<TaskInstance: etl_dag.update_postgres_table manual__2023-09-14T09:36:11.986322+00:00 [queued]>
[2023-09-14T09:36:16.101+0000] {taskinstance.py:1157} INFO - Dependencies all met for dep_context=requeueable deps ti=<TaskInstance: etl_dag.update_postgres_table manual__2023-09-14T09:36:11.986322+00:00 [queued]>
[2023-09-14T09:36:16.102+0000] {taskinstance.py:1359} INFO - Starting attempt 1 of 2
[2023-09-14T09:36:16.106+0000] {taskinstance.py:1380} INFO - Executing <Task(PythonOperator): update_postgres_table> on 2023-09-14 09:36:11.986322+00:00
[2023-09-14T09:36:16.109+0000] {standard_task_runner.py:57} INFO - Started process 103 to run task
[2023-09-14T09:36:16.111+0000] {standard_task_runner.py:84} INFO - Running: ['***', 'tasks', 'run', 'etl_dag', 'update_postgres_table', 'manual__2023-09-14T09:36:11.986322+00:00', '--job-id', '6', '--raw', '--subdir', 'DAGS_FOLDER/etl_dag.py', '--cfg-path', '/tmp/tmp4d97s9de']
[2023-09-14T09:36:16.113+0000] {standard_task_runner.py:85} INFO - Job 6: Subtask update_postgres_table
[2023-09-14T09:36:16.138+0000] {task_command.py:415} INFO - Running <TaskInstance: etl_dag.update_postgres_table manual__2023-09-14T09:36:11.986322+00:00 [running]> on host 79bfd5ddbbec
[2023-09-14T09:36:16.171+0000] {taskinstance.py:1660} INFO - Exporting env vars: AIRFLOW_CTX_DAG_OWNER='admin' AIRFLOW_CTX_DAG_ID='etl_dag' AIRFLOW_CTX_TASK_ID='update_postgres_table' AIRFLOW_CTX_EXECUTION_DATE='2023-09-14T09:36:11.986322+00:00' AIRFLOW_CTX_TRY_NUMBER='1' AIRFLOW_CTX_DAG_RUN_ID='manual__2023-09-14T09:36:11.986322+00:00'
[2023-09-14T09:36:16.262+0000] {taskinstance.py:1935} ERROR - Task failed with exception
Traceback (most recent call last):
  File "/home/airflow/.local/lib/python3.8/site-packages/airflow/operators/python.py", line 192, in execute
    return_value = self.execute_callable()
  File "/home/airflow/.local/lib/python3.8/site-packages/airflow/operators/python.py", line 209, in execute_callable
    return self.python_callable(*self.op_args, **self.op_kwargs)
  File "/opt/airflow/dags/etl_dag.py", line 35, in _update_postgres_table
    connection = json.loads(extract_connection)
NameError: name 'json' is not defined
[2023-09-14T09:36:16.268+0000] {taskinstance.py:1398} INFO - Marking task as UP_FOR_RETRY. dag_id=etl_dag, task_id=update_postgres_table, execution_date=20230914T093611, start_date=20230914T093616, end_date=20230914T093616
[2023-09-14T09:36:16.272+0000] {standard_task_runner.py:104} ERROR - Failed to execute job 6 for task update_postgres_table (name 'json' is not defined; 103)
[2023-09-14T09:36:16.283+0000] {local_task_job_runner.py:228} INFO - Task exited with return code 1
[2023-09-14T09:36:16.295+0000] {taskinstance.py:2776} INFO - 0 downstream tasks scheduled from follow-on schedule check
